{"uuid": "0e6a18fa-cf27-4a73-87f8-f123f1c67b9d", "children": ["1e12d1be-34d3-41a3-a551-3c0e9a51846c"], "befores": [{"name": "open_app_without_login", "status": "broken", "statusDetails": {"message": "selenium.common.exceptions.WebDriverException: Message: An unknown server-side error occurred while processing the command. Original error: Device R9HN70VWB5J was not in the list of connected devices\nStacktrace:\nUnknownError: An unknown server-side error occurred while processing the command. Original error: Device R9HN70VWB5J was not in the list of connected devices\n    at getResponseForW3CError (C:\\Users\\a.jamshidi\\AppData\\Roaming\\npm\\node_modules\\appium\\node_modules\\@appium\\base-driver\\lib\\protocol\\errors.js:1145:9)\n    at asyncHandler (C:\\Users\\a.jamshidi\\AppData\\Roaming\\npm\\node_modules\\appium\\node_modules\\@appium\\base-driver\\lib\\protocol\\protocol.js:485:57)\n", "trace": "  File \"C:\\Users\\a.jamshidi\\android_automation\\android_automation\\.venv\\lib\\site-packages\\pluggy\\_callers.py\", line 167, in _multicall\n    teardown.throw(outcome._exception)\n  File \"C:\\Users\\a.jamshidi\\android_automation\\android_automation\\.venv\\lib\\site-packages\\_pytest\\setuponly.py\", line 36, in pytest_fixture_setup\n    return (yield)\n  File \"C:\\Users\\a.jamshidi\\android_automation\\android_automation\\.venv\\lib\\site-packages\\pluggy\\_callers.py\", line 103, in _multicall\n    res = hook_impl.function(*args)\n  File \"C:\\Users\\a.jamshidi\\android_automation\\android_automation\\.venv\\lib\\site-packages\\_pytest\\fixtures.py\", line 1140, in pytest_fixture_setup\n    result = call_fixture_func(fixturefunc, request, kwargs)\n  File \"C:\\Users\\a.jamshidi\\android_automation\\android_automation\\.venv\\lib\\site-packages\\_pytest\\fixtures.py\", line 891, in call_fixture_func\n    fixture_result = next(generator)\n  File \"G:\\android_automation\\conftest.py\", line 59, in open_app_without_login\n    driver = webdriver.Remote(appium_url, options=options)\n  File \"C:\\Users\\a.jamshidi\\android_automation\\android_automation\\.venv\\lib\\site-packages\\appium\\webdriver\\webdriver.py\", line 229, in __init__\n    super().__init__(\n  File \"C:\\Users\\a.jamshidi\\android_automation\\android_automation\\.venv\\lib\\site-packages\\selenium\\webdriver\\remote\\webdriver.py\", line 212, in __init__\n    self.start_session(capabilities)\n  File \"C:\\Users\\a.jamshidi\\android_automation\\android_automation\\.venv\\lib\\site-packages\\appium\\webdriver\\webdriver.py\", line 319, in start_session\n    response = self.execute(RemoteCommand.NEW_SESSION, w3c_caps)\n  File \"C:\\Users\\a.jamshidi\\android_automation\\android_automation\\.venv\\lib\\site-packages\\selenium\\webdriver\\remote\\webdriver.py\", line 354, in execute\n    self.error_handler.check_response(response)\n  File \"C:\\Users\\a.jamshidi\\android_automation\\android_automation\\.venv\\lib\\site-packages\\selenium\\webdriver\\remote\\errorhandler.py\", line 229, in check_response\n    raise exception_class(message, screen, stacktrace)\n"}, "start": 1729603127522, "stop": 1729603130838}], "start": 1729603127522, "stop": 1729603130863}